Workbook

Sheet Sheet1
A1: Host | B1: Group | C1: Name | D1: Asset tag | F1: class
A2: TUV_Batsumber_Sugnugur_Unitel | B2: All_sites, Tuv, zte_rectifiers | C2: TUV_Batsumber_Sugnugur_Unitel | D2: 260302-260313- 165330/1 | E2: =VLOOKUP(D2,Sheet2!E:Q,13,FALSE) -> C | F2: C
A3: UVS.Hovd_ShiverBag_TungetiinOroiUul_MP25 | B3: All_sites, Solar, Uvs, solar_huawei | C3: UVS_Hovd_ShiverBag_TungetiinOroiUul | D3: 11-T-85-00078 | E3: =VLOOKUP(D3,Sheet2!E:Q,13,FALSE) -> D | F3: D
A4: UVS.Ulaangom_HarhiraaHotel_MP25 | B4: All_sites, Rect_HUAWEI_SMU02B, Uvs | C4: UVS_Ulaangom_HarhiraaHotel | D4: 11-T-85-00077 | E4: =VLOOKUP(D4,Sheet2!E:Q,13,FALSE) -> C | F4: C
A5: UVS.Tarialan_TeeliinSuurin_MP25 | B5: All_sites, Solar, Uvs, solar_huawei | C5: UVS_Tarialan_TeeliinSuurin | D5: 11-T-85-00076 | E5: =VLOOKUP(D5,Sheet2!E:Q,13,FALSE) -> D | F5: D
A6: UVS.Naranbulag_ZostiinHutul_MP25 | B6: All_sites, Solar, Uvs, solar_huawei | C6: UVS_Naranbulag_ZostiinHutul | D6: 11-T-85-00075 | E6: =VLOOKUP(D6,Sheet2!E:Q,13,FALSE) -> D | F6: D
A7: UVS.Zuungovi_UguumurBag_IhUlaanUul_MP24 | B7: All_sites, Solar, Uvs, solar_huawei | C7: UVS_Zuungovi_UguumurBag_IhUlaanUul | D7: 11-T-85-00073 | E7: =VLOOKUP(D7,Sheet2!E:Q,13,FALSE) -> D | F7: D
A8: UVS.Ulaangom_9bag_Buyant27_25aToot_MP24 | B8: All_sites, Rect_HUAWEI_SMU02B, Uvs | C8: UVS_Ulaangom_9bag_Buyant27-25aToot | D8: 11-T-85-00072 | E8: =VLOOKUP(D8,Sheet2!E:Q,13,FALSE) -> C | F8: C
A9: UVS.Ulaangom_Airport_MP24 | B9: All_sites, Rect_HUAWEI_SMU02B, Uvs, ameter | C9: UVS_Ulaangom_Airport | D9: 11-T-85-00069 | E9: =VLOOKUP(D9,Sheet2!E:Q,13,FALSE) -> C | F9: C
A10: UVS.Ulaangom_5bag_UlaanUul | B10: All_sites, Rect_HUAWEI_SMU02B, Uvs, ameter | C10: UVS_Ulaangom_5bag_UlaanUul | D10: 11-T-85-00068 | E10: =VLOOKUP(D10,Sheet2!E:Q,13,FALSE) -> C | F10: C
A11: UVS.Ulaangom_Nomin_NMD110 | B11: All_sites, Uvs, ZTE_YDN | C11: UVS_Ulaangom_Nomin | D11: 11-T-85-00067 | E11: =VLOOKUP(D11,Sheet2!E:Q,13,FALSE) -> B | F11: B
A12: UVS.Umnugovi_UliastBag | B12: All_sites, Solar, Uvs | C12: UVS_Umnugovi_UliastBag | D12: 11-T-85-00066 | E12: =VLOOKUP(D12,Sheet2!E:Q,13,FALSE) -> F | F12: F
A13: UVS.Tes_SharsuuriBoomt | B13: All_sites, Rect_HUAWEI_SMU02B, Uvs, ameter | C13: UVS_Tes_SharSuuriBoomt | D13: 11-T-85-00064 | E13: =VLOOKUP(D13,Sheet2!E:Q,13,FALSE) -> D | F13: D
... A1657: CHD._16xor_Khailaast_DU_LLC_NMD30_ULN | B1657: All_sites, ULN_Chingelgei_duureg, Ulaanbaatar | C1657: ULN_CHD_16hor_Hailaast_D&U_LLC | D1657: 11-T-15-00095 | E1657: =VLOOKUP(D1657,Sheet2!E:Q,13,FALSE) -> B | F1657: B
A1658: DC.TCB.rsu | B1658: All_sites, DC, DC_Status | C1658: TCB-1 | D1658: 11-T-15-00053 | E1658: =VLOOKUP(D1658,Sheet2!E:Q,13,FALSE) -> #N/A | F1658: #N/A
A1659: CHD.CrownCenter_ISS100_ULN | B1659: 1Phase, All_sites, ULN_Chingelgei_duureg, Ulaanbaatar | C1659: ULN_CHD_CrownCenter | D1659: 11-T-15-00043 | E1659: =VLOOKUP(D1659,Sheet2!E:Q,13,FALSE) -> C | F1659: C
A1660: CHD._19hor_GuntiinAmniiEhHoidUul_ULN | B1660: All_sites, ULN_Chingelgei_duureg, Ulaanbaatar | C1660: ULN_CHD_19hor_GuntiinAmniiEhHoidUul | D1660: 11-T-15-00041 | E1660: =VLOOKUP(D1660,Sheet2!E:Q,13,FALSE) -> C | F1660: C
A1661: CHD._4hor_TSEG_MShUTuv_ISS100_ULN | B1661: All_sites, Rect_HUAWEI_SMU02B, ULN_Chingelgei_duureg, Ulaanbaatar | C1661: ULN_CHD_4hor_TSEG_MShUTuv | D1661: 11-T-15-00039 | E1661: =VLOOKUP(D1661,Sheet2!E:Q,13,FALSE) -> B | F1661: B
A1662: CHD.JigjidZuslan_ISS100_ULN | B1662: All_sites, ULN_Chingelgei_duureg, Ulaanbaatar | C1662: ULN_CHD_JigjidZuslan | D1662: 11-T-15-00038 | E1662: =VLOOKUP(D1662,Sheet2!E:Q,13,FALSE) -> D | F1662: D
A1663: CHD._2hor_OronZai_NMD110_ULN | B1663: All_sites, Rect_HUAWEI_SMU02B, ULN_Chingelgei_duureg, Ulaanbaatar | C1663: ULN_CHD_2hor_OronZai | D1663: 11-T-15-00037 | E1663: =VLOOKUP(D1663,Sheet2!E:Q,13,FALSE) -> B | F1663: B
A1664: CHD._6HOR_9bair_NMD_ULN | B1664: All_sites, ULN_Chingelgei_duureg, Ulaanbaatar | C1664: ULN_CHD_6hor_9Bair | D1664: 11-T-15-00035 | E1664: =VLOOKUP(D1664,Sheet2!E:Q,13,FALSE) -> B | F1664: B
A1665: CHD._18hor_Shadivlan_ULN | B1665: All_sites, ULN_Chingelgei_duureg, Ulaanbaatar, ZTE_YDN | C1665: ULN_CHD_18hor_Shadivlan | D1665: 11-T-15-00032 | E1665: =VLOOKUP(D1665,Sheet2!E:Q,13,FALSE) -> B | F1665: B
A1666: CHD._6xor_58Bair_NMD30_ULN | B1666: All_sites, ULN_Chingelgei_duureg, Ulaanbaatar, ZTE_YDN | C1666: ULN_CHD_6hor_58Bair | D1666: 11-T-15-00031 | E1666: =VLOOKUP(D1666,Sheet2!E:Q,13,FALSE) -> B | F1666: B
A1667: CHD._3hor_PeaceTower_ISS100_ULN | B1667: 1Phase, All_sites, Rect_HUAWEI_SMU02B, ULN_Chingelgei_duureg, Ulaanbaatar | C1667: ULN_CHD_3hor_PeaceTower | D1667: 11-T-15-00028 | E1667: =VLOOKUP(D1667,Sheet2!E:Q,13,FALSE) -> C | F1667: C
A1668: CHD._1hor_TDBTuulSalbar_ISS100_ULN | B1668: All_sites, Rect_HUAWEI_SMU02B, ULN_Chingelgei_duureg, Ulaanbaatar | C1668: ULN_CHD_1hor_TDBTuulSalbar | D1668: 11-T-15-00025 | E1668: =VLOOKUP(D1668,Sheet2!E:Q,13,FALSE) -> C | F1668: C
A1669: CHD._3hor_MongolNews_MOS42_ULN | B1669: 1Phase, All_sites, ULN_Chingelgei_duureg, Ulaanbaatar | C1669: ULN_CHD_3hor_MongolNews | D1669: 11-T-15-00024 | E1669: =VLOOKUP(D1669,Sheet2!E:Q,13,FALSE) -> B | F1669: B
A1670: CHD._15hor_Hailaast_Unitel_ISS100_ULN | B1670: All_sites, Rect_HUAWEI_SMU02B, ULN_Chingelgei_duureg, Ulaanbaatar | C1670: ULN_CHD_15hor_Hailaast_Unitel | D1670: 11-T-15-00023 | E1670: =VLOOKUP(D1670,Sheet2!E:Q,13,FALSE) -> B | F1670: B
... A1986: BND.MW204_ULN | B1986: All_sites, ULN_Baganuur_duureg, Ulaanbaatar | C1986: ULN_BND_MW204 | D1986: 11-T-10-00001 | E1986: =VLOOKUP(D1986,Sheet2!E:Q,13,FALSE) -> C | F1986: C

Sheet Sheet2
A1: № | B1: id | C1: Ажлын төлөв | D1: Ажлын тоо | E1: Код | F1: Сайт | G1: Үл тохирол | H1: Тайлагнасан огноо | I1: Төлөв | J1: Байршил/Аймаг/Хот | K1: Байршил/Сум/Дүүрэг | L1: Байршил/Баг/Хороо | M1: Байршил/Байршил | N1: Бусад мэдээлэл/Бүсчлэл | O1: Бусад мэдээлэл/Харьяалал | P1: Бусад мэдээлэл/Ассан огноо | Q1: Бусад мэдээлэл/Зэрэглэл | R1: Cellname/2g | S1: Cellname/3g | T1: Cellname/4g | U1: Cellname/5g | V1: Бусад мэдээлэл/Хариуцагч | W1: Хэрэглэгч | X1: URL | Y1: Бусад мэдээлэл/Эзэмшигч | Z1: checkKeyId | AA1: what3words | AB1: latLongCoordinate
A2: 1 | B2: 17485587875672 | C2: Асаахад бэлдэж байна | E2: 260401-260402- 163809/1 | F2: Нэр олгоогүй | G2: 0 | I2: Асаахад бэлдэж байна | J2: Хөвсгөл | K2: Мөрөн | L2: 1-р баг | W2: tsamba | X2: https://sm.mobicom.mn/mdobject/dataview/1525387912476&dv[id][]=17485587875672
A3: 2 | B3: 17485583430642 | C3: Байгуулж байна | D3: 18 | E3: 11-T-83-00080 | F3: BAU_Ulgii_13Bag_KazakhstanDelguur | G3: 0 | I3: Шийдэл тодорхойлж байна | J3: Баян-Өлгий | K3: Өлгий | L3: 13-р баг, Жана ауыл | M3: Баян-Өлгий аймаг Өлгий сум 13-р баг Казакстандэлгүүр | N3: Аймгийн төв | O3: ROC_URC_BAU | Q3: B | T3: BAU_S4_Tuv13BagKazahkstanDelguur-1 BAU_S4_Tuv13BagKazahkstanDelguur-2 BAU_S4_Tuv13BagKazahkstanDelguur-3 BAU_S4_Tuv13BagKazahkstanDelguur_B7-1 BAU_S4_Tuv13BagKazahkstanDelguur_B7-2 BAU_S4_Tuv13BagKazahkstanDelguur_B7-3 BAU_S4_Tuv13BagKazahkstanDelguur_B1-1 BAU_S4_Tuv13BagKazahkstanDelguur_B1-2 BAU_S4_Tuv13BagKazahkstanDelguur_B1-3 | V3: Mobicom | W3: battulga | X3: https://sm.mobicom.mn/mdobject/dataview/1525387912476&dv[id][]=17485583430642 | Y3: Бусад | Z3: 17485583430642 | AB3: 89.961777777777783172|48.963558333333338624
A4: 3 | B4: 17485571456372 | C4: Байгуулж байна | D4: 7 | E4: 11-T-15-00185 | F4: ULN_CHD_5hor_GeserSum_RFID_Sector | G4: 0 | I4: Хэрэгжилтд шилжүүлж байна | J4: Улаанбаатар | K4: Чингэлтэй | L4: 5-р хороо | M4: Улаанбаатар хот Чингэлтэй дүүрэг 5-р хороо Гэсэр сүмийн урд гэрлийн шон дээр | N4: Улаанбаатар | O4: ID_Planning | P4: 46112 | Q4: F | T4: UB_H4_sCHD5horGeserSumLightPole-1 (UB_Gandan) UB_H4_sCHD5horGeserSumLightPole-2(UB_Gandan) | W4: sergelen.u | X4: https://sm.mobicom.mn/mdobject/dataview/1525387912476&dv[id][]=17485571456372 | Y4: Бусад | Z4: 17485571456372 | AB4: 47.91674471367652,106.9163167476654
A5: 4 | B5: 17485571456302 | C5: Байгуулж байна | D5: 8 | E5: 11-T-46-00181 | F5: UMG_Dalanzadgad_8Bag_DZApartment_9Bair | G5: 0 | I5: СДБ-н ажил гүйцэтгэж байна | J5: Өмнөговь | K5: Даланзадгад | M5: Өмнөговь аймаг Даланзадгад хот Даланзадгад апартмент 9-р байрны дээвэрт | N5: Аймгийн төв | O5: ROC_GRC_UMG | P5: 46111 | Q5: B | S5: UMG_A3_Tuv8BagDZApartment-1 UMG_A3_Tuv8BagDZApartment-2 UMG_A3_Tuv8BagDZApartment-3 | T5: UMG_H4_Tuv8BagDZApartment-1 UMG_H4_Tuv8BagDZApartment-2 UMG_H4_Tuv8BagDZApartment-3 UMG_H4_Tuv8BagDZApartment_B7-1 UMG_H4_Tuv8BagDZApartment_B7-2 UMG_H4_Tuv8BagDZApartment_B7-3 UMG_H4_Tuv8BagDZApartment_B28-2 UMG_H4_Tuv8BagDZApartment_B28-3 | W5: sergelen.u | X5: https://sm.mobicom.mn/mdobject/dataview/1525387912476&dv[id][]=17485571456302 | Y5: Мобиком | Z5: 17485571456302 | AB5: 43.572809,104.434485
A6: 5 | B6: 17485570967712 | C6: Хэвийн | D6: 9 | E6: 11-T-67-00101 | F6: Huv_Murun_8Bag_DalaiVanSurguuli | G6: 0 | I6: Хэвийн | J6: Хөвсгөл | K6: Мөрөн | L6: 8-р баг | M6: Хөвсгөл аймаг Мөрөн хот, 8-р баг, ДалайВан сургуулийн 3давхарт. | N6: Аймгийн төв | O6: ROC_ERC_HUV | P6: 46106 | Q6: B | T6: HUV_H4_Tuv8BagDalaiVanSurguuli-1 HUV_H4_Tuv8BagDalaiVanSurguuli-2 HUV_H4_Tuv8BagDalaiVanSurguuli-3 | W6: ankhbayar.g | X6: https://sm.mobicom.mn/mdobject/dataview/1525387912476&dv[id][]=17485570967712 | Y6: Мобиком | Z6: 17485570967712 | AB6: 49.629971,100.159474
A7: 6 | B7: 17485552214692 | C7: Хэвийн | D7: 11 | E7: 11-T-17-00217 | F7: ULN_HUD_8hor_TashgaiAguulah | G7: 0 | H7: 46094.376 | I7: Хэвийн | J7: Улаанбаатар | K7: Хан-Уул | L7: 8-р хороо | N7: Улаанбаатар | W7: tuguldur.enkh | X7: https://sm.mobicom.mn/mdobject/dataview/1525387912476&dv[id][]=17485552214692 | Z7: 17485552214692 | AB7: 47.83904660507439,106.79110769000393
A8: 7 | B8: 17485552157112 | C8: Хэвийн | D8: 13 | E8: 11-T-17-00295 | F8: ULN_HUD_8hor_TCB2_SolarPowerPlant | G8: 0 | H8: 46093.124 | I8: Хэвийн | J8: Улаанбаатар | K8: Хан-Уул | L8: 8-р хороо | N8: Улаанбаатар | W8: tuguldur.enkh | X8: https://sm.mobicom.mn/mdobject/dataview/1525387912476&dv[id][]=17485552157112 | Z8: 17485552157112 | AB8: 47.838909220010024,106.79058624046513
A9: 8 | B9: 17485542104942 | C9: Хэвийн | D9: 46 | E9: 16-T-13-00252 | F9: ULN_BZD_3hor_MojoKaraoke_Femto | G9: 0 | I9: Хэвийн | J9: Улаанбаатар | K9: Баянзүрх | L9: 3-р хороо | M9: Сансрын тунел &quot;Можо кареоке&quot; B1 давхарт | N9: Улаанбаатар | O9: RAND_RDOD | P9: 46086 | Q9: F | T9: UB_B4_Femto_MojoKareoke-1 | V9: мобиком | W9: Sainjargal | X9: https://sm.mobicom.mn/mdobject/dataview/1525387912476&dv[id][]=17485542104942 | Y9: Мобиком | Z9: 17485542104942 | AB9: 47.91674471367652,106.9163167476654
A10: 9 | B10: 17485539545732 | C10: Байгуулж байна | D10: 5 | E10: 260305-260405- 075123/2 | F10: Нэр олгоогүй | G10: 0 | I10: Ашиглалтанд шилжүүлж байна | J10: Завхан | K10: Тосонцэнгэл | L10: 6-р баг, Идэр | W10: sergelen.u | X10: https://sm.mobicom.mn/mdobject/dataview/1525387912476&dv[id][]=17485539545732
A11: 10 | B11: 17485539545662 | C11: Байгуулж байна | D11: 5 | E11: 260305-260405- 075123/1 | F11: Нэр олгоогүй | G11: 0 | I11: Ашиглалтанд шилжүүлж байна | J11: Увс | K11: Тэс | L11: 1-р баг | W11: sergelen.u | X11: https://sm.mobicom.mn/mdobject/dataview/1525387912476&dv[id][]=17485539545662
A12: 11 | B12: 17485536693922 | C12: Байгуулж байна | D12: 14 | E12: 11-T-46-00180 | F12: UMG_Dalanzadgad_6Bag_Niseh2-203A2block | G12: 0 | I12: Хэрэгжилтд шилжүүлж байна | J12: Өмнөговь | K12: Даланзадгад | L12: хануул | M12: Өмнөговь аймаг, Даланзадгад сум, Их уулын 6-р баг, Нисэх 2-203А/2 | N12: Аймгийн төв | Q12: B | W12: nasanjargal.g | X12: https://sm.mobicom.mn/mdobject/dataview/1525387912476&dv[id][]=17485536693922 | Z12: 17485536693922 | AB12: 43.572809,104.434485
A13: 12 | B13: 17485536688452 | C13: Байгуулж байна | D13: 16 | E13: 251201-260601- 164200/1 | F13: Нэр олгоогүй | G13: 0 | I13: Ашиглалтанд шилжүүлж байна | J13: Өмнөговь | K13: Даланзадгад | L13: Далан | W13: nasanjargal.g | X13: https://sm.mobicom.mn/mdobject/dataview/1525387912476&dv[id][]=17485536688452
A14: 13 | B14: 17485534896532 | C14: Хэвийн | D14: 5 | E14: 260302-260313- 165330/1 | F14: TUV_Batsumber_Sugnugur_Unitel | G14: 0 | I14: Хэвийн | J14: Төв | K14: Батсүмбэр | L14: 3-р баг, Баянгол | M14: Төв аймаг, Батсүмбэр сум, Сөгнөгөр 3-р баг, айлын хашаанд, Юнителийн сайт дотор | N14: Орон нутаг | O14: ID_Planning | P14: 46092 | Q14: C | T14: TUV_B4_BatsumberSugnugurUnitel1-1 TUV_B4_BatsumberSugnugurUnitel2-1 | V14: Юнитель ХХК -ны харуул хариуцна. | W14: ankhbayar.g | X14: https://sm.mobicom.mn/mdobject/dataview/1525387912476&dv[id][]=17485534896532 | Y14: Юнител | Z14: 17485534896532 | AB14: 48.391482,106.854723
A15: 14 | B15: 17485534744212 | C15: Хэвийн | D15: 45 | E15: 11-T-15-00184 | F15: ULN_CHD_1hor_CapitalCenter_1301_Femto | G15: 0 | I15: Хэвийн | J15: Улаанбаатар | K15: Чингэлтэй | L15: 1-р хороо | M15: Улаанбаатар хот Чингэлтэй дүүрэг 1-р хороо Capital center 13давхар | N15: Улаанбаатар | O15: RAND_RDOD | P15: 46085 | Q15: F | T15: UB_B4_Femto_Capitalcenter | W15: tsamba | X15: https://sm.mobicom.mn/mdobject/dataview/1525387912476&dv[id][]=17485534744212 | Y15: Бусад | Z15: 17485534744212 | AB15: 47.91879,106.901936
A16: 15 | B16: 17485511881512 | C16: Байгуулж байна | D16: 17 | E16: 11-T-41-00145 | F16: TUV_Lun_AltganaResource | G16: 0 | I16: СДБ-н ажил гүйцэтгэж байна | J16: Төв | K16: Лүн | L16: 2-р баг, Өгөөмөр | M16: Төв аймаг Лүн сум Алтгана ресурс | N16: Орон нутаг | Q16: D | W16: nasanjargal.g | X16: https://sm.mobicom.mn/mdobject/dataview/1525387912476&dv[id][]=17485511881512 | Z16: 17485511881512 | AB16: 47.979674,104.975055
A17: 16 | B17: 17485505708212 | C17: Хэвийн | D17: 7 | E17: 11-T-21-00082 | F17: DOR_Herlen_5bag_Diviz_Netcom | G17: 0 | H17: 46107.105 | I17: Хэвийн | J17: Дорнод | K17: Хэрлэн | L17: 5-р баг | M17: Дорнод аймгийн төв Хэрлэн сумын 5-р баг, Неткомын байр цамхагтай сайт | N17: Аймгийн төв | O17: ROC_URC_DOR | Q17: C | T17: DOR_B4_Herlen5bagNetcom_B8-1 DOR_B4_Herlen5bagNetcom_B8-2 DOR_B4_Herlen5bagNetcom_B8-3 | W17: erdenetsogt | X17: https://sm.mobicom.mn/mdobject/dataview/1525387912476&dv[id][]=17485505708212 | Y17: МХС | Z17: 17485505708212 | AB17: 48.062758,114.6365
A18: 17 | B18: 17485502307992 | C18: Хэвийн | D18: 44 | E18: 11-T-17-00303 | F18: ULN_HUD_17hor_IhMongolPlaza_Femto | G18: 0 | I18: Хэвийн | J18: Улаанбаатар | K18: Хан-Уул | L18: 18-р хороо | M18: ХУД, 17-р хороо, Ихмонгол плаза дотор байрлах &quot;Хаан банк&quot; | N18: Улаанбаатар | O18: ID_System | P18: 46063 | Q18: F | T18: UB_B4_IhMongolPlaza-1 | W18: Sainjargal | X18: https://sm.mobicom.mn/mdobject/dataview/1525387912476&dv[id][]=17485502307992 | Y18: Мобиком | Z18: 17485502307992 | AB18: 47.91674471367652,106.9163167476654
A19: 18 | B19: 17485501597932 | C19: Байгуулж байна | D19: 13 | E19: 11-T-16-00162 | F19: ULN_BGD_20hor_Bars2_Femto | G19: 0 | I19: Хэрэгжилтд шилжүүлж байна | J19: Улаанбаатар | K19: Баянгол | L19: 21-р хороо | M19: Барс-2 худалдааны төв | N19: Улаанбаатар | O19: ID_Planning | P19: 46099 | Q19: F | T19: UB_B4_Femto_iBGD20horBars2-1 UB_B4_Femto_iBGD20horBars2-2 | V19: bars2 zah | W19: battulga | X19: https://sm.mobicom.mn/mdobject/dataview/1525387912476&dv[id][]=17485501597932 | Y19: Бусад | Z19: 17485501597932 | AB19: 106.83166111111110297|47.910044444444444878
A20: 19 | B20: 17485492935012 | C20: Байгуулж байна | D20: 7 | E20: 11-T-17-00302 | F20: ULN_HUD_22hor_KunzSurguuli | G20: 0 | I20: Хэрэгжилтд шилжүүлж байна | J20: Улаанбаатар | K20: Хан-Уул | L20: 22-р хороо | M20: Улаанбаатар хот Хан Уул дүүрэг 22-р хороо Күнз сургуулийн дээвэр дээр минишелтер байрлуулсан | N20: Улаанбаатар | O20: ID_Planning | P20: 46079 | Q20: B | T20: UB_H4_HUD22horKunzSurguuli-1 UB_H4_HUD22horKunzSurguuli-2 UB_H4_HUD22horKunzSurguuli-3 | W20: sergelen.u | X20: https://sm.mobicom.mn/mdobject/dataview/1525387912476&dv[id][]=17485492935012 | Y20: Мобиком | Z20: 17485492935012 | AB20: 47.871562859556725,106.90519022139105
A21: 20 | B21: 17485481032202 | C21: Байгуулж байна | D21: 44 | E21: 11-T-17-00304 16-T-17-00304 | F21: ULN_HUD_6hor_KhanBankDataCenter_Femto | G21: 0 | I21: Хэрэгжилтд шилжүүлж байна | J21: Улаанбаатар | K21: Хан-Уул | L21: 6-р хороо | M21: ХУД, 6-р хороо, &quot;Хаан банк дата центр&quot; | N21: Улаанбаатар | O21: ID_System | P21: 46014 | Q21: F | T21: UB_B4_Femto_DataHall-1 | W21: Sainjargal | X21: https://sm.mobicom.mn/mdobject/dataview/1525387912476&dv[id][]=17485481032202 | Y21: Мобиком | Z21: 17485481032202 | AB21: 47.8429830242326,106.7966526
A22: 21 | B22: 17485446416552 | C22: Байгуулж байна | D22: 6 | E22: 11-T-62-00085 | F22: UVH_Nariinteel_ArtsBag_Indert | G22: 0 | I22: Хэрэгжилтд шилжүүлж байна | J22: Өвөрхангай | K22: Нарийнтээл | L22: Арц баг | M22: Өвөрхангай аймагНарийнтээл сум Арц баг Индэрт | N22: Орон нутаг | O22: ROC_URC_UVH | Q22: D | W22: erdenetsogt | X22: https://sm.mobicom.mn/mdobject/dataview/1525387912476&dv[id][]=17485446416552 | Y22: Мобиком | Z22: 17485446416552 | AB22: 46.034604,101.353135
A23: 22 | B23: 17485431678702 | C23: Байгуулж байна | D23: 44 | E23: 11-T-17-00293 | F23: ULN_HUD_15hor_TavanBogdMachinery_Femto | G23: 0 | I23: Хэрэгжилтд шилжүүлж байна | J23: Улаанбаатар | K23: Хан-Уул | L23: 15-р хороо | M23: УБ хот Хан уул дүүрэг 15-р хороо Tavanbogd Machinery | N23: Улаанбаатар | O23: ID_System | P23: 45649 | Q23: F | T23: UB_B4_Femto_Tavanbogdmachinery | V23: IT-99023371 | W23: Sainjargal | X23: https://sm.mobicom.mn/mdobject/dataview/1525387912476&dv[id][]=17485431678702 | Z23: 17485431678702 | AB23: 47.91674471367652,106.9163167476654
A24: 23 | B24: 17485431511712 | C24: Байгуулж байна | D24: 44 | E24: 11-T-44-00089 | F24: DOG_Hatanbulag_HiliinTsergiin0169Angi_Bo | G24: 0 | I24: Хэрэгжилтд шилжүүлж байна | J24: Дорноговь | K24: Эрдэнэ | L24: 1-р баг, Бүрдэнэ | M24: Хилийн цэргийн 0169 дүгээр анги | N24: Орон нутаг | O24: ROC_GRC_DOG | P24: 45506 | Q24: D | T24: DOG_B4_Femto_Erdene_Zastav-4_UzuurUs DOG_B4_Femto_Erdene_Zastav-1_ElsenDaravgai DOG_B4_Femto_Erdene_Zastav-3 DOG_B4_Femto_Erdene_Zastav-6 DOG_B4_Femto_Erdene_Zastav-8 DOG_B4_Femto_Erdene_Zastav-9 | W24: Sainjargal | X24: https://sm.mobicom.mn/mdobject/dataview/1525387912476&dv[id][]=17485431511712 | Y24: Мобиком | Z24: 17485431511712 | AB24: 44.4446897521094,111.091169415635
A25: 24 | B25: 17485423795612 | C25: Хэвийн | D25: 19 | E25: 11-T-83-00077 | F25: BAU_Buyant_2Bag_UlaanHutliinOroi | G25: 0 | I25: Хэвийн | J25: Баян-Өлгий | K25: Буянт | L25: 2-р баг, Хөлцөөт | M25: Баян-Өлгий аймаг Буянт сум 2-р баг Хөлцөөт баг Улаан хөтлийн орой | N25: Орон нутаг | O25: ROC_URC_BAU | P25: 46022 | Q25: F | T25: BAU_H4_Buyant2BagUlaanHutliinOroi_B8-1 BAU_H4_Buyant2BagUlaanHutliinOroi_B8-2 | V25: Mobicom | W25: battulga | X25: https://sm.mobicom.mn/mdobject/dataview/1525387912476&dv[id][]=17485423795612 | Y25: МХС | Z25: 17485423795612 | AB25: 89.627883333333329574|48.563288888888884287
A26: 25 | B26: 17485423559292 | C26: Хэвийн | D26: 17 | E26: 11-T-82-00070 | F26: GOA_Esunbulag_NaranbulagBag_HanAltai | G26: 0 | H26: 46105.036 | I26: Хэвийн | J26: Говь-Алтай | K26: Есөнбулаг | L26: 3-р баг, Жаргалант | M26: Говь-Алтай аймаг, Есөнбулаг сум, Наранбулаг баг, Хан Алтай ресорс, Амралтын байр | N26: Орон нутаг | O26: ROC_URC_GOA | P26: 46014 | Q26: D | T26: GOA_H4_EsunbulagNaranbulagBagHanAltai-1 GOA_H4_EsunbulagNaranbulagBagHanAltai-2 GOA_H4_EsunbulagNaranbulagBagHanAltai-3 | V26: Mobicom | W26: battulga | X26: https://sm.mobicom.mn/mdobject/dataview/1525387912476&dv[id][]=17485423559292 | Y26: Мобиком | Z26: 17485423559292 | AB26: 96.869222222222219898|46.069700000000004536
A27: 26 | B27: 17485422147402 | C27: Байгуулж байна | D27: 11 | E27: 11-T-17-00297 | F27: ULN_HUD_15hor_TusgaltOffice | G27: 0 | I27: Хэрэгжилтд шилжүүлж байна | J27: Улаанбаатар | K27: Хан-Уул | L27: 15-р хороо | M27: Улаанбаатар хот Хан-Уул дүүрэг 15-р хороо Тусгалт оффис | N27: Улаанбаатар | O27: ID_Planning | P27: 46015 | Q27: B | T27: UB_H4_HUD15horTusgaltOffice-1 UB_H4_HUD15horTusgaltOffice-2 UB_H4_HUD15horTusgaltOffice-3 UB_H4_HUD15horTusgaltOffice_B7-1 UB_H4_HUD15horTusgaltOffice_B7-3 UB_H4_HUD15horTusgaltOffice_B28-1 | U27: UB_H5_HUD15horTusgaltOffice-1 UB_H5_HUD15horTusgaltOffice-2 UB_H5_HUD15horTusgaltOffice-3 | W27: nasanjargal.g | X27: https://sm.mobicom.mn/mdobject/dataview/1525387912476&dv[id][]=17485422147402 | Y27: Мобиком | Z27: 17485422147402 | AB27: 47.908014624687354,106.92314028739929
A28: 27 | B28: 17485421926612 | C28: Байгуулж байна | D28: 17 | E28: 11-T-48-00051 | F28: DUG_Saintsagaan_Uizenbag_HongoriinUul | G28: 0 | I28: Угсралт хийгдэж байна | J28: Дундговь | K28: Сайнцагаан | L28: 4-р баг, Үйзэн | M28: Дундговь аймаг Сайнцагаан сум 4-р баг Үйзэн баг Хонгорын уул | N28: Орон нутаг | O28: ROC_GRC_DUG | P28: 46022 | Q28: F | R28: DUG_H2_SaintsagaanUizenBag-1 DUG_H2_SaintsagaanUizenBag-2 | T28: DUG_H4_SaintsagaanUizenBag_B8-1 DUG_H4_SaintsagaanUizenBag_B8-2 | W28: nasanjargal.g | X28: https://sm.mobicom.mn/mdobject/dataview/1525387912476&dv[id][]=17485421926612 | Y28: Мобиком | Z28: 17485421926612 | AB28: 45.496324,106.445328
A29: 28 | B29: 17485419051382 | C29: Байгуулж байна | D29: 44 | E29: 11-T-21-0007 | F29: DOR_Herlen_1bag_DornodGuril_Femto | G29: 0 | I29: Хэрэгжилтд шилжүүлж байна | J29: Дорнод | K29: Хэрлэн | L29: 1-р баг | M29: Дорнод аймаг, Чойбалсан хот, 1-р баг Дорнод гурил ххк | N29: Орон нутаг | O29: ROC_URC_DOR | P29: 45821 | Q29: F | T29: DOR_B4_Femto_Guril-1 DOR_B4_Femto_Guril-2 DOR_B4_Femto_Guril-3 | W29: Sainjargal | X29: https://sm.mobicom.mn/mdobject/dataview/1525387912476&dv[id][]=17485419051382 | Y29: Мобиком | Z29: 17485419051382 | AB29: 47.91674471367652,106.9163167476654
A30: 29 | B30: 17485419027682 | C30: Байгуулж байна | D30: 44 | E30: 11-T-44-00091 | F30: DOG_Erdene_HiliinTsergiin0129Angi_Femto | G30: 0 | I30: Хэрэгжилтд шилжүүлж байна | J30: Дорноговь | K30: Эрдэнэ | L30: 3-р баг, Цагаан хөтөл | M30: Дорноговь аймаг, Эрдэнэ сум Хилийн цэргийн 0129 дүгээр анги | N30: Орон нутаг | O30: ROC_GRC_DOG | P30: 45654 | Q30: D | W30: Sainjargal | X30: https://sm.mobicom.mn/mdobject/dataview/1525387912476&dv[id][]=17485419027682 | Y30: Мобиком | Z30: 17485419027682 | AB30: 47.91674471367652,106.9163167476654
A31: 30 | B31: 17485419006062 | C31: Байгуулж байна | D31: 44 | E31: 11-T-41-00144 | F31: TUV_Bayan_Buuruljuut_Femto | G31: 0 | I31: Хэрэгжилтд шилжүүлж байна | J31: Төв | K31: Баян | L31: 2-р баг, Өгөөмөр | M31: Төв аймаг Баян сум Бөөрөлжүүт | N31: Улаанбаатар | O31: ID_System | P31: 45649 | Q31: F | T31: TUV_B4_Femto_Buuruljuut_1Floor TUV_B4_Femto_Buuruljuut_2Floor | W31: Sainjargal | X31: https://sm.mobicom.mn/mdobject/dataview/1525387912476&dv[id][]=17485419006062 | Z31: 17485419006062 | AB31: 47.2416656722207,107.802937079663
A32: 31 | B32: 17485418978462 | C32: Байгуулж байна | D32: 44 | E32: 11-T-14-00274 | F32: ULN_SBD_1hor_ICTGroup_Femto | G32: 0 | I32: Хэрэгжилтд шилжүүлж байна | J32: Улаанбаатар | K32: Хан-Уул | L32: 15-р хороо | M32: Улаанбаатар хот ,Сүхбаатар дүүрэг ,1-р хороо, Ай си ти групп | N32: Улаанбаатар | O32: ID_System | P32: 45506 | Q32: F | T32: UB_B4_Femto_ICTgroup_office-1 | W32: Sainjargal | X32: https://sm.mobicom.mn/mdobject/dataview/1525387912476&dv[id][]=17485418978462 | Y32: Мобиком | Z32: 17485418978462 | AB32: 47.9130646360479,106.927054973409
A33: 32 | B33: 17485418924162 | C33: Байгуулж байна | D33: 44 | E33: 11-T-61-00106 | F33: ORH_BayanUndur_ZesErdeneOffice_Femto | G33: 0 | I33: Шийдэл тодорхойлж байна | J33: Орхон | K33: Баян-Өндөр | L33: 3-р баг, Уурхайчин | M33: Орхон аймаг Баянөндөр сум 3-р микро Зэс эрдэнэ оффис | N33: Орон нутаг | O33: ROC_ERC | P33: 45821 | Q33: F | T33: ORH_B4_Femto_ZeserdeneOFfice | W33: Sainjargal | X33: https://sm.mobicom.mn/mdobject/dataview/1525387912476&dv[id][]=17485418924162 | Y33: Мобиком | Z33: 17485418924162 | AB33: 104.05652999999999508|49.026159999999997297
A34: 33 | B34: 17485418401552 | C34: Байгуулж байна | D34: 44 | E34: 11-T-21-00078 | F34: DOR_Halhgol_SumberBoomt_Femto | G34: 0 | I34: Шийдэл тодорхойлж байна | J34: Дорнод | K34: Халхгол | L34: 1-р баг, Сүмбэр | M34: Дорнод аймаг Халх гол сум Сүмбэр боомт | N34: Орон нутаг | O34: ROC_URC_DOR | P34: 45649 | Q34: F | T34: DOR_B4_Femto_Sumberboomt-1 DOR_B4_Femto_Sumberboomt-2 | V34: Холбооны дарга: Энхжаргал 89110665 | W34: Sainjargal | X34: https://sm.mobicom.mn/mdobject/dataview/1525387912476&dv[id][]=17485418401552 | Y34: Мобиком | Z34: 17485418401552 | AB34: 47.91674471367652,106.9163167476654
A35: 34 | B35: 17485418360672 | C35: Байгуулж байна | D35: 44 | E35: 11-T-21-00079 | F35: DOR_Halhgol_ZadgaitBoomt_Femto | G35: 0 | I35: Хайгуул хийгдэж байгаа | J35: Дорнод | K35: Халхгол | L35: 1-р баг, Сүмбэр | M35: Дорнод Халхгол сум Задгайт боомт | N35: Орон нутаг | O35: ROC_URC_DOR | P35: 45634 | Q35: F | T35: DOR_B4_Femto_ZadgaitZastav DOR_B4_Femto_ZadgaitZastav-2 | V35: Холбооны дарга: Энхжаргал 89110665 | W35: Sainjargal | X35: https://sm.mobicom.mn/mdobject/dataview/1525387912476&dv[id][]=17485418360672 | Y35: Мобиком | Z35: 17485418360672 | AB35: 46.8271336665276,118.71954925427019
A36: 35 | B36: 17485411760722 | C36: Байгуулж байна | D36: 17 | E36: 11-T-82-00071 | F36: GOA_Esunbulag_NaranbulagBag_sHanAltai | G36: 0 | I36: Ашиглалтанд шилжүүлж байна | J36: Говь-Алтай | K36: Есөнбулаг | L36: 3-р баг, Жаргалант | M36: Говь-Алтай аймаг, Есөнбулаг сум, Наранбулаг баг, Хан Алтай ресорс, Олборлолтын бүс | N36: Орон нутаг | O36: ROC_URC_GOA | P36: 46014 | Q36: D | T36: GOA_H4_sEsunbulagNaranbulagBagHanAltai-1 | V36: Mobicom | W36: battulga | X36: https://sm.mobicom.mn/mdobject/dataview/1525387912476&dv[id][]=17485411760722 | Y36: Бусад | Z36: 17485411760722 | AB36: 96.946591666666677156|46.107738888888889051
A37: 36 | B37: 17485410703742 | C37: Хэвийн | D37: 9 | E37: 251201-251231- 174841/1 | F37: Нэр олгоогүй | G37: 0 | I37: Хэвийн | J37: Улаанбаатар | K37: Хан-Уул | L37: 8-р хороо | W37: demberelsambuu | X37: https://sm.mobicom.mn/mdobject/dataview/1525387912476&dv[id][]=17485410703742
A38: 37 | B38: 17485410027462 | C38: Байгуулж байна | D38: 9 | E38: 11-T-81-00068 | F38: ZAV_Tosontsengel_TosonEnergy | G38: 0 | I38: Ашиглалтанд шилжүүлж байна | J38: Завхан | K38: Тосонцэнгэл | L38: 3-р баг, Улаантолгой | M38: Завхан аймаг Тосонцэнгэл сум 3-р баг Улаантолгой, Тосон Энержи | N38: Орон нутаг | O38: ROC_URC_ZAV | P38: 46017 | Q38: C | T38: ZAV_H4_TosontsengelTosonEnergy-1 ZAV_H4_TosontsengelTosonEnergy-2 | W38: sergelen.u | X38: https://sm.mobicom.mn/mdobject/dataview/1525387912476&dv[id][]=17485410027462 | Y38: Мобиком | Z38: 17485410027462 | AB38: 48.75394557198505,98.29093934650261
A39: 38 | B39: 17485408275042 | C39: Байгуулж байна | D39: 44 | E39: 11-T-41-00146 | F39: TUV_Zuunmod_1bag_MongolTuurgatanTeatr | G39: 0 | I39: Угсралт хийгдэж байна | J39: Төв | K39: Зуунмод | L39: 1-р баг, Номт | M39: Төв аймаг, Зуун мод сум, 1-р баг, Монгол туургатан театр-н дээвэр лүү гарах хэсгийн шатны тавцан дээр байрлалтай сайт. | N39: Аймгийн төв | O39: ID_Planning | P39: 46017 | Q39: B | S39: TUV_H3_TuvMongolTuurgatanTeatr-1 TUV_H3_TuvMongolTuurgatanTeatr-2 TUV_H3_TuvMongolTuurgatanTeatr-3 | T39: TUV_TuvMongolTuurgatanTeatr-1 TUV_TuvMongolTuurgatanTeatr-2 TUV_TuvMongolTuurgatanTeatr-3 TUV_H4_TuvMongolTuurgatanTeatr_B28-1 | W39: baterdene.tu | X39: https://sm.mobicom.mn/mdobject/dataview/1525387912476&dv[id][]=17485408275042 | Y39: Мобиком | Z39: 17485408275042 | AB39: 47.70541534956726,106.94250583648682
A40: 39 | B40: 17485406780672 | C40: Байгуулж байна | D40: 6 | E40: 11-T-62-00086 | F40: UVH_Ulziit_Guulinbag_HunOvoo | G40: 0 | I40: Хэрэгжилтд шилжүүлж байна | J40: Өвөрхангай | K40: Өлзийт | L40: Гуулин баг | M40: Өвөрхангай аймаг Өлзийт сум Гуулин баг Хүн овоо | N40: Орон нутаг | Q40: D | W40: erdenetsogt | X40: https://sm.mobicom.mn/mdobject/dataview/1525387912476&dv[id][]=17485406780672 | Y40: Мобиком | Z40: 17485406780672 | AB40: 46.54799,103.369338
...
